<?xml version="1.0" encoding="UTF-8"?>
<!-- Generated by org.testng.reporters.JUnitXMLReporter -->
<testsuite ignored="7" hostname="DESKTOP-KKPJ5RQ" failures="1" tests="1" name="Default test" time="44.72" errors="0" timestamp="2024-04-08T22:16:30 IST">
  <testcase classname="HomeLyf.test.User" name="userSignUp" time="27.45">
    <failure type="java.lang.AssertionError" message="expected [200] but found [404]">
      <![CDATA[java.lang.AssertionError: expected [200] but found [404]
at org.testng.Assert.fail(Assert.java:111)
at org.testng.Assert.failNotEquals(Assert.java:1578)
at org.testng.Assert.assertEqualsImpl(Assert.java:150)
at org.testng.Assert.assertEquals(Assert.java:132)
at org.testng.Assert.assertEquals(Assert.java:1419)
at org.testng.Assert.assertEquals(Assert.java:1383)
at org.testng.Assert.assertEquals(Assert.java:1429)
at HomeLyf.test.User.userSignUp(User.java:46)
at java.base/jdk.internal.reflect.DirectMethodHandleAccessor.invoke(DirectMethodHandleAccessor.java:103)
at java.base/java.lang.reflect.Method.invoke(Method.java:580)
at org.testng.internal.invokers.MethodInvocationHelper.invokeMethod(MethodInvocationHelper.java:139)
at org.testng.internal.invokers.TestInvoker.invokeMethod(TestInvoker.java:664)
at org.testng.internal.invokers.TestInvoker.invokeTestMethod(TestInvoker.java:228)
at org.testng.internal.invokers.MethodRunner.runInSequence(MethodRunner.java:63)
at org.testng.internal.invokers.TestInvoker$MethodInvocationAgent.invoke(TestInvoker.java:961)
at org.testng.internal.invokers.TestInvoker.invokeTestMethods(TestInvoker.java:201)
at org.testng.internal.invokers.TestMethodWorker.invokeTestMethods(TestMethodWorker.java:148)
at org.testng.internal.invokers.TestMethodWorker.run(TestMethodWorker.java:128)
at java.base/java.util.ArrayList.forEach(ArrayList.java:1596)
at org.testng.TestRunner.privateRun(TestRunner.java:819)
at org.testng.TestRunner.run(TestRunner.java:619)
at org.testng.SuiteRunner.runTest(SuiteRunner.java:443)
at org.testng.SuiteRunner.runSequentially(SuiteRunner.java:437)
at org.testng.SuiteRunner.privateRun(SuiteRunner.java:397)
at org.testng.SuiteRunner.run(SuiteRunner.java:336)
at org.testng.SuiteRunnerWorker.runSuite(SuiteRunnerWorker.java:52)
at org.testng.SuiteRunnerWorker.run(SuiteRunnerWorker.java:95)
at org.testng.TestNG.runSuitesSequentially(TestNG.java:1301)
at org.testng.TestNG.runSuitesLocally(TestNG.java:1228)
at org.testng.TestNG.runSuites(TestNG.java:1134)
at org.testng.TestNG.run(TestNG.java:1101)
at org.testng.remote.AbstractRemoteTestNG.run(AbstractRemoteTestNG.java:115)
at org.testng.remote.RemoteTestNG.initAndRun(RemoteTestNG.java:251)
at org.testng.remote.RemoteTestNG.main(RemoteTestNG.java:77)
]]>
    </failure>
  </testcase> <!-- userSignUp -->
  <testcase classname="HomeLyf.test.User" name="sendInvalidEmail" time="0.0">
    <ignored/>
  </testcase> <!-- sendInvalidEmail -->
  <testcase classname="HomeLyf.test.User" name="userLogin" time="0.0">
    <ignored/>
  </testcase> <!-- userLogin -->
  <testcase classname="HomeLyf.test.User" name="sendEmailOTP" time="0.0">
    <ignored/>
  </testcase> <!-- sendEmailOTP -->
  <testcase classname="HomeLyf.test.User" name="invaliduserSignUp" time="0.0">
    <ignored/>
  </testcase> <!-- invaliduserSignUp -->
  <testcase classname="HomeLyf.test.User" name="forgot_PassInvalidData" time="0.0">
    <ignored/>
  </testcase> <!-- forgot_PassInvalidData -->
  <testcase classname="HomeLyf.test.User" name="forgot_Pass" time="0.0">
    <ignored/>
  </testcase> <!-- forgot_Pass -->
  <testcase classname="HomeLyf.test.User" name="userLogin_With_Invalid_Data" time="0.0">
    <ignored/>
  </testcase> <!-- userLogin_With_Invalid_Data -->
</testsuite> <!-- Default test -->
