<?xml version="1.0" encoding="UTF-8"?>
<testng-results ignored="0" total="4" passed="0" failed="4" skipped="0">
  <reporter-output>
  </reporter-output>
  <suite started-at="2024-06-10T15:26:00 IST" name="Default suite" finished-at="2024-06-10T15:26:30 IST" duration-ms="30399">
    <groups>
    </groups>
    <test started-at="2024-06-10T15:26:00 IST" name="Default test" finished-at="2024-06-10T15:26:30 IST" duration-ms="30399">
      <class name="HomeLyf.test.Customer">
        <test-method signature="userLogin(org.testng.ITestContext,java.lang.String,java.lang.String,java.lang.String,java.lang.String,java.lang.String)[pri:1, instance:HomeLyf.test.Customer@1253e7cb]" started-at="2024-06-10T15:26:06 IST" name="userLogin" data-provider="Customerlogin" finished-at="2024-06-10T15:26:22 IST" duration-ms="15766" status="FAIL">
          <params>
            <param index="0">
              <value>
                <![CDATA[org.testng.TestRunner@4fe875be]]>
              </value>
            </param>
            <param index="1">
              <value>
                <![CDATA[6029860554]]>
              </value>
            </param>
            <param index="2">
              <value>
                <![CDATA[C]]>
              </value>
            </param>
            <param index="3">
              <value>
                <![CDATA[mkoganur95@gmail.com]]>
              </value>
            </param>
            <param index="4">
              <value>
                <![CDATA[String@123]]>
              </value>
            </param>
            <param index="5">
              <value>
                <![CDATA[pune]]>
              </value>
            </param>
          </params>
          <exception class="io.restassured.path.json.exception.JsonPathException">
            <message>
              <![CDATA[Failed to parse the JSON document]]>
            </message>
            <full-stacktrace>
              <![CDATA[io.restassured.path.json.exception.JsonPathException: Failed to parse the JSON document
at io.restassured.path.json.JsonPath$ExceptionCatcher.invoke(JsonPath.java:1002)
at io.restassured.path.json.JsonPath$4.doParseWith(JsonPath.java:967)
at io.restassured.path.json.JsonPath$JsonParser.parseWith(JsonPath.java:1047)
at io.restassured.path.json.JsonPath.get(JsonPath.java:202)
at io.restassured.path.json.JsonPath.getString(JsonPath.java:352)
at HomeLyf.test.Customer.userLogin(Customer.java:33)
at java.base/jdk.internal.reflect.DirectMethodHandleAccessor.invoke(DirectMethodHandleAccessor.java:103)
at java.base/java.lang.reflect.Method.invoke(Method.java:580)
at org.testng.internal.invokers.MethodInvocationHelper.invokeMethod(MethodInvocationHelper.java:139)
at org.testng.internal.invokers.TestInvoker.invokeMethod(TestInvoker.java:664)
at org.testng.internal.invokers.TestInvoker.invokeTestMethod(TestInvoker.java:228)
at org.testng.internal.invokers.MethodRunner.runInSequence(MethodRunner.java:63)
at org.testng.internal.invokers.TestInvoker$MethodInvocationAgent.invoke(TestInvoker.java:961)
at org.testng.internal.invokers.TestInvoker.invokeTestMethods(TestInvoker.java:201)
at org.testng.internal.invokers.TestMethodWorker.invokeTestMethods(TestMethodWorker.java:148)
at org.testng.internal.invokers.TestMethodWorker.run(TestMethodWorker.java:128)
at java.base/java.util.ArrayList.forEach(ArrayList.java:1596)
at org.testng.TestRunner.privateRun(TestRunner.java:819)
at org.testng.TestRunner.run(TestRunner.java:619)
at org.testng.SuiteRunner.runTest(SuiteRunner.java:443)
at org.testng.SuiteRunner.runSequentially(SuiteRunner.java:437)
at org.testng.SuiteRunner.privateRun(SuiteRunner.java:397)
at org.testng.SuiteRunner.run(SuiteRunner.java:336)
at org.testng.SuiteRunnerWorker.runSuite(SuiteRunnerWorker.java:52)
at org.testng.SuiteRunnerWorker.run(SuiteRunnerWorker.java:95)
at org.testng.TestNG.runSuitesSequentially(TestNG.java:1301)
at org.testng.TestNG.runSuitesLocally(TestNG.java:1228)
at org.testng.TestNG.runSuites(TestNG.java:1134)
at org.testng.TestNG.run(TestNG.java:1101)
at org.testng.remote.AbstractRemoteTestNG.run(AbstractRemoteTestNG.java:115)
at org.testng.remote.RemoteTestNG.initAndRun(RemoteTestNG.java:251)
at org.testng.remote.RemoteTestNG.main(RemoteTestNG.java:77)
Caused by: groovy.json.JsonException: Lexing failed on line: 1, column: 1, while reading '<', no possible valid JSON value or punctuation could be recognized.
at groovy.json.JsonLexer.nextToken(JsonLexer.java:86)
at groovy.json.JsonLexer$nextToken.call(Unknown Source)
at org.codehaus.groovy.runtime.callsite.CallSiteArray.defaultCall(CallSiteArray.java:47)
at org.codehaus.groovy.runtime.callsite.AbstractCallSite.call(AbstractCallSite.java:125)
at org.codehaus.groovy.runtime.callsite.AbstractCallSite.call(AbstractCallSite.java:130)
at io.restassured.internal.path.json.ConfigurableJsonSlurper.parse(ConfigurableJsonSlurper.groovy:97)
at io.restassured.internal.path.json.ConfigurableJsonSlurper$parse.callCurrent(Unknown Source)
at org.codehaus.groovy.runtime.callsite.CallSiteArray.defaultCallCurrent(CallSiteArray.java:51)
at org.codehaus.groovy.runtime.callsite.AbstractCallSite.callCurrent(AbstractCallSite.java:171)
at org.codehaus.groovy.runtime.callsite.AbstractCallSite.callCurrent(AbstractCallSite.java:185)
at io.restassured.internal.path.json.ConfigurableJsonSlurper.parseText(ConfigurableJsonSlurper.groovy:83)
at io.restassured.path.json.JsonPath$4$1.method(JsonPath.java:965)
at io.restassured.path.json.JsonPath$ExceptionCatcher.invoke(JsonPath.java:1000)
... 31 more
]]>
            </full-stacktrace>
          </exception> <!-- io.restassured.path.json.exception.JsonPathException -->
          <reporter-output>
          </reporter-output>
        </test-method> <!-- userLogin -->
        <test-method signature="customer_service(org.testng.ITestContext)[pri:2, instance:HomeLyf.test.Customer@1253e7cb]" started-at="2024-06-10T15:26:22 IST" name="customer_service" finished-at="2024-06-10T15:26:25 IST" duration-ms="2922" status="FAIL">
          <params>
            <param index="0">
              <value>
                <![CDATA[org.testng.TestRunner@4fe875be]]>
              </value>
            </param>
          </params>
          <exception class="java.lang.AssertionError">
            <message>
              <![CDATA[expected [200] but found [404]]]>
            </message>
            <full-stacktrace>
              <![CDATA[java.lang.AssertionError: expected [200] but found [404]
at org.testng.Assert.fail(Assert.java:111)
at org.testng.Assert.failNotEquals(Assert.java:1578)
at org.testng.Assert.assertEqualsImpl(Assert.java:150)
at org.testng.Assert.assertEquals(Assert.java:132)
at org.testng.Assert.assertEquals(Assert.java:1419)
at org.testng.Assert.assertEquals(Assert.java:1383)
at org.testng.Assert.assertEquals(Assert.java:1429)
at HomeLyf.test.Customer.customer_service(Customer.java:49)
at java.base/jdk.internal.reflect.DirectMethodHandleAccessor.invoke(DirectMethodHandleAccessor.java:103)
at java.base/java.lang.reflect.Method.invoke(Method.java:580)
at org.testng.internal.invokers.MethodInvocationHelper.invokeMethod(MethodInvocationHelper.java:139)
at org.testng.internal.invokers.TestInvoker.invokeMethod(TestInvoker.java:664)
at org.testng.internal.invokers.TestInvoker.invokeTestMethod(TestInvoker.java:228)
at org.testng.internal.invokers.MethodRunner.runInSequence(MethodRunner.java:63)
at org.testng.internal.invokers.TestInvoker$MethodInvocationAgent.invoke(TestInvoker.java:961)
at org.testng.internal.invokers.TestInvoker.invokeTestMethods(TestInvoker.java:201)
at org.testng.internal.invokers.TestMethodWorker.invokeTestMethods(TestMethodWorker.java:148)
at org.testng.internal.invokers.TestMethodWorker.run(TestMethodWorker.java:128)
at java.base/java.util.ArrayList.forEach(ArrayList.java:1596)
at org.testng.TestRunner.privateRun(TestRunner.java:819)
at org.testng.TestRunner.run(TestRunner.java:619)
at org.testng.SuiteRunner.runTest(SuiteRunner.java:443)
at org.testng.SuiteRunner.runSequentially(SuiteRunner.java:437)
at org.testng.SuiteRunner.privateRun(SuiteRunner.java:397)
at org.testng.SuiteRunner.run(SuiteRunner.java:336)
at org.testng.SuiteRunnerWorker.runSuite(SuiteRunnerWorker.java:52)
at org.testng.SuiteRunnerWorker.run(SuiteRunnerWorker.java:95)
at org.testng.TestNG.runSuitesSequentially(TestNG.java:1301)
at org.testng.TestNG.runSuitesLocally(TestNG.java:1228)
at org.testng.TestNG.runSuites(TestNG.java:1134)
at org.testng.TestNG.run(TestNG.java:1101)
at org.testng.remote.AbstractRemoteTestNG.run(AbstractRemoteTestNG.java:115)
at org.testng.remote.RemoteTestNG.initAndRun(RemoteTestNG.java:251)
at org.testng.remote.RemoteTestNG.main(RemoteTestNG.java:77)
]]>
            </full-stacktrace>
          </exception> <!-- java.lang.AssertionError -->
          <reporter-output>
          </reporter-output>
        </test-method> <!-- customer_service -->
        <test-method signature="getUserLookupCategory()[pri:12, instance:HomeLyf.test.Customer@1253e7cb]" started-at="2024-06-10T15:26:25 IST" name="getUserLookupCategory" finished-at="2024-06-10T15:26:27 IST" duration-ms="2692" status="FAIL">
          <exception class="io.restassured.path.json.exception.JsonPathException">
            <message>
              <![CDATA[Failed to parse the JSON document]]>
            </message>
            <full-stacktrace>
              <![CDATA[io.restassured.path.json.exception.JsonPathException: Failed to parse the JSON document
at io.restassured.path.json.JsonPath$ExceptionCatcher.invoke(JsonPath.java:1002)
at io.restassured.path.json.JsonPath$4.doParseWith(JsonPath.java:967)
at io.restassured.path.json.JsonPath$JsonParser.parseWith(JsonPath.java:1047)
at io.restassured.path.json.JsonPath.get(JsonPath.java:202)
at io.restassured.path.json.JsonPath.getInt(JsonPath.java:237)
at HomeLyf.test.Customer.getUserLookupCategory(Customer.java:60)
at java.base/jdk.internal.reflect.DirectMethodHandleAccessor.invoke(DirectMethodHandleAccessor.java:103)
at java.base/java.lang.reflect.Method.invoke(Method.java:580)
at org.testng.internal.invokers.MethodInvocationHelper.invokeMethod(MethodInvocationHelper.java:139)
at org.testng.internal.invokers.TestInvoker.invokeMethod(TestInvoker.java:664)
at org.testng.internal.invokers.TestInvoker.invokeTestMethod(TestInvoker.java:228)
at org.testng.internal.invokers.MethodRunner.runInSequence(MethodRunner.java:63)
at org.testng.internal.invokers.TestInvoker$MethodInvocationAgent.invoke(TestInvoker.java:961)
at org.testng.internal.invokers.TestInvoker.invokeTestMethods(TestInvoker.java:201)
at org.testng.internal.invokers.TestMethodWorker.invokeTestMethods(TestMethodWorker.java:148)
at org.testng.internal.invokers.TestMethodWorker.run(TestMethodWorker.java:128)
at java.base/java.util.ArrayList.forEach(ArrayList.java:1596)
at org.testng.TestRunner.privateRun(TestRunner.java:819)
at org.testng.TestRunner.run(TestRunner.java:619)
at org.testng.SuiteRunner.runTest(SuiteRunner.java:443)
at org.testng.SuiteRunner.runSequentially(SuiteRunner.java:437)
at org.testng.SuiteRunner.privateRun(SuiteRunner.java:397)
at org.testng.SuiteRunner.run(SuiteRunner.java:336)
at org.testng.SuiteRunnerWorker.runSuite(SuiteRunnerWorker.java:52)
at org.testng.SuiteRunnerWorker.run(SuiteRunnerWorker.java:95)
at org.testng.TestNG.runSuitesSequentially(TestNG.java:1301)
at org.testng.TestNG.runSuitesLocally(TestNG.java:1228)
at org.testng.TestNG.runSuites(TestNG.java:1134)
at org.testng.TestNG.run(TestNG.java:1101)
at org.testng.remote.AbstractRemoteTestNG.run(AbstractRemoteTestNG.java:115)
at org.testng.remote.RemoteTestNG.initAndRun(RemoteTestNG.java:251)
at org.testng.remote.RemoteTestNG.main(RemoteTestNG.java:77)
Caused by: groovy.json.JsonException: Lexing failed on line: 1, column: 1, while reading '<', no possible valid JSON value or punctuation could be recognized.
at groovy.json.JsonLexer.nextToken(JsonLexer.java:86)
at groovy.json.JsonLexer$nextToken.call(Unknown Source)
at io.restassured.internal.path.json.ConfigurableJsonSlurper.parse(ConfigurableJsonSlurper.groovy:97)
at io.restassured.internal.path.json.ConfigurableJsonSlurper$parse.callCurrent(Unknown Source)
at io.restassured.internal.path.json.ConfigurableJsonSlurper.parseText(ConfigurableJsonSlurper.groovy:83)
at io.restassured.path.json.JsonPath$4$1.method(JsonPath.java:965)
at io.restassured.path.json.JsonPath$ExceptionCatcher.invoke(JsonPath.java:1000)
... 31 more
]]>
            </full-stacktrace>
          </exception> <!-- io.restassured.path.json.exception.JsonPathException -->
          <reporter-output>
          </reporter-output>
        </test-method> <!-- getUserLookupCategory -->
        <test-method signature="getSubCateogryId()[pri:13, instance:HomeLyf.test.Customer@1253e7cb]" started-at="2024-06-10T15:26:27 IST" name="getSubCateogryId" finished-at="2024-06-10T15:26:30 IST" duration-ms="3040" status="FAIL">
          <exception class="java.lang.AssertionError">
            <message>
              <![CDATA[expected [200] but found [404]]]>
            </message>
            <full-stacktrace>
              <![CDATA[java.lang.AssertionError: expected [200] but found [404]
at org.testng.Assert.fail(Assert.java:111)
at org.testng.Assert.failNotEquals(Assert.java:1578)
at org.testng.Assert.assertEqualsImpl(Assert.java:150)
at org.testng.Assert.assertEquals(Assert.java:132)
at org.testng.Assert.assertEquals(Assert.java:1419)
at org.testng.Assert.assertEquals(Assert.java:1383)
at org.testng.Assert.assertEquals(Assert.java:1429)
at HomeLyf.test.Customer.getSubCateogryId(Customer.java:70)
at java.base/jdk.internal.reflect.DirectMethodHandleAccessor.invoke(DirectMethodHandleAccessor.java:103)
at java.base/java.lang.reflect.Method.invoke(Method.java:580)
at org.testng.internal.invokers.MethodInvocationHelper.invokeMethod(MethodInvocationHelper.java:139)
at org.testng.internal.invokers.TestInvoker.invokeMethod(TestInvoker.java:664)
at org.testng.internal.invokers.TestInvoker.invokeTestMethod(TestInvoker.java:228)
at org.testng.internal.invokers.MethodRunner.runInSequence(MethodRunner.java:63)
at org.testng.internal.invokers.TestInvoker$MethodInvocationAgent.invoke(TestInvoker.java:961)
at org.testng.internal.invokers.TestInvoker.invokeTestMethods(TestInvoker.java:201)
at org.testng.internal.invokers.TestMethodWorker.invokeTestMethods(TestMethodWorker.java:148)
at org.testng.internal.invokers.TestMethodWorker.run(TestMethodWorker.java:128)
at java.base/java.util.ArrayList.forEach(ArrayList.java:1596)
at org.testng.TestRunner.privateRun(TestRunner.java:819)
at org.testng.TestRunner.run(TestRunner.java:619)
at org.testng.SuiteRunner.runTest(SuiteRunner.java:443)
at org.testng.SuiteRunner.runSequentially(SuiteRunner.java:437)
at org.testng.SuiteRunner.privateRun(SuiteRunner.java:397)
at org.testng.SuiteRunner.run(SuiteRunner.java:336)
at org.testng.SuiteRunnerWorker.runSuite(SuiteRunnerWorker.java:52)
at org.testng.SuiteRunnerWorker.run(SuiteRunnerWorker.java:95)
at org.testng.TestNG.runSuitesSequentially(TestNG.java:1301)
at org.testng.TestNG.runSuitesLocally(TestNG.java:1228)
at org.testng.TestNG.runSuites(TestNG.java:1134)
at org.testng.TestNG.run(TestNG.java:1101)
at org.testng.remote.AbstractRemoteTestNG.run(AbstractRemoteTestNG.java:115)
at org.testng.remote.RemoteTestNG.initAndRun(RemoteTestNG.java:251)
at org.testng.remote.RemoteTestNG.main(RemoteTestNG.java:77)
]]>
            </full-stacktrace>
          </exception> <!-- java.lang.AssertionError -->
          <reporter-output>
          </reporter-output>
        </test-method> <!-- getSubCateogryId -->
      </class> <!-- HomeLyf.test.Customer -->
    </test> <!-- Default test -->
  </suite> <!-- Default suite -->
</testng-results>
